Traceback (most recent call last):
  File "C:\Users\jump2\AppData\Local\Programs\Python\Python311\Lib\site-packages\requests\models.py", line 971, in json
    return complexjson.loads(self.text, **kwargs)
           ^^^^^^^^^^^^^^^^^^^^^^^^^^^^^^^^^^^^^^
  File "C:\Users\jump2\AppData\Local\Programs\Python\Python311\Lib\json\__init__.py", line 346, in loads
    return _default_decoder.decode(s)
           ^^^^^^^^^^^^^^^^^^^^^^^^^^
  File "C:\Users\jump2\AppData\Local\Programs\Python\Python311\Lib\json\decoder.py", line 337, in decode
    obj, end = self.raw_decode(s, idx=_w(s, 0).end())
               ^^^^^^^^^^^^^^^^^^^^^^^^^^^^^^^^^^^^^^
  File "C:\Users\jump2\AppData\Local\Programs\Python\Python311\Lib\json\decoder.py", line 355, in raw_decode
    raise JSONDecodeError("Expecting value", s, err.value) from None
json.decoder.JSONDecodeError: Expecting value: line 2 column 1 (char 1)

During handling of the above exception, another exception occurred:

Traceback (most recent call last):
  File "c:\Users\jump2\Documents\GitHub\MEDALWARE-PROJECT\src\data_miner.py", line 101, in <module>
    data_updater()
  File "c:\Users\jump2\Documents\GitHub\MEDALWARE-PROJECT\src\data_miner.py", line 95, in data_updater
    df = data_extractor()
         ^^^^^^^^^^^^^^^^
  File "c:\Users\jump2\Documents\GitHub\MEDALWARE-PROJECT\src\data_miner.py", line 28, in data_extractor
    if response_sha.json()["query_status"] == "hash_not_found":
       ^^^^^^^^^^^^^^^^^^^
  File "C:\Users\jump2\AppData\Local\Programs\Python\Python311\Lib\site-packages\requests\models.py", line 975, in json
    raise RequestsJSONDecodeError(e.msg, e.doc, e.pos)
requests.exceptions.JSONDecodeError: Expecting value: line 2 column 1 (char 1)
